Traceback (most recent call last):
  File "/home/celien/miniconda3/lib/python3.11/site-packages/jupyter_cache/executors/utils.py", line 58, in single_nb_execution
    executenb(
  File "/home/celien/miniconda3/lib/python3.11/site-packages/nbclient/client.py", line 1314, in execute
    return NotebookClient(nb=nb, resources=resources, km=km, **kwargs).execute()
           ^^^^^^^^^^^^^^^^^^^^^^^^^^^^^^^^^^^^^^^^^^^^^^^^^^^^^^^^^^^^^^^^^^^^^
  File "/home/celien/miniconda3/lib/python3.11/site-packages/jupyter_core/utils/__init__.py", line 165, in wrapped
    return loop.run_until_complete(inner)
           ^^^^^^^^^^^^^^^^^^^^^^^^^^^^^^
  File "/home/celien/miniconda3/lib/python3.11/asyncio/base_events.py", line 653, in run_until_complete
    return future.result()
           ^^^^^^^^^^^^^^^
  File "/home/celien/miniconda3/lib/python3.11/site-packages/nbclient/client.py", line 709, in async_execute
    await self.async_execute_cell(
  File "/home/celien/miniconda3/lib/python3.11/site-packages/nbclient/client.py", line 1062, in async_execute_cell
    await self._check_raise_for_error(cell, cell_index, exec_reply)
  File "/home/celien/miniconda3/lib/python3.11/site-packages/nbclient/client.py", line 918, in _check_raise_for_error
    raise CellExecutionError.from_cell_and_msg(cell, exec_reply_content)
nbclient.exceptions.CellExecutionError: An error occurred while executing the following cell:
------------------
import utils

utils.print_percentage_missing_values(df_fraud)
------------------


[0;31m---------------------------------------------------------------------------[0m
[0;31mModuleNotFoundError[0m                       Traceback (most recent call last)
Cell [0;32mIn[2], line 1[0m
[0;32m----> 1[0m [38;5;28;01mimport[39;00m [38;5;21;01mutils[39;00m
[1;32m      3[0m utils[38;5;241m.[39mprint_percentage_missing_values(df_fraud)

File [0;32m~/Documents/ML/ml_partial3/docs/utils.py:4[0m
[1;32m      2[0m [38;5;28;01mimport[39;00m [38;5;21;01mpandas[39;00m [38;5;28;01mas[39;00m [38;5;21;01mpd[39;00m
[1;32m      3[0m [38;5;28;01mimport[39;00m [38;5;21;01mnumpy[39;00m [38;5;28;01mas[39;00m [38;5;21;01mnp[39;00m
[0;32m----> 4[0m [38;5;28;01mfrom[39;00m [38;5;21;01mstatsmodels[39;00m[38;5;21;01m.[39;00m[38;5;21;01mstats[39;00m[38;5;21;01m.[39;00m[38;5;21;01moutliers_influence[39;00m [38;5;28;01mimport[39;00m variance_inflation_factor
[1;32m      5[0m [38;5;28;01mfrom[39;00m [38;5;21;01mtqdm[39;00m [38;5;28;01mimport[39;00m tqdm
[1;32m      6[0m [38;5;28;01mimport[39;00m [38;5;21;01mitertools[39;00m

[0;31mModuleNotFoundError[0m: No module named 'statsmodels'

